Workbook

Sheet TH
A1: Ngày | B1: Nội dung | C1: Số tiền | D1: Người được thăm | E1: Cán bộ công nhân viên | F1: QH | G1: Lý do | H1: Trả tiền
A2: 46048 | B2: Chi tiền viếng bố đẻ đc Lò Văn Sơn – CĐ Hạ tấng | C2: 800000 | E2: Lò Văn Sơn | G2: Mất
A3: 46055 | B3: Chi tiền tặng quà ĐVCĐ nghỉ việc CĐ TT Hạ tầng | C3: 2500000
A4: 46066 | B4: Chi tien tham vo dc Tuan sinh con CD TT Ha tang | C4: 300000 | E4: Đồng chí Tuấn
A5: 46063 | B5: Chứng từ chi tiền sinh nhật quý 4/2025 | C5: 14100000
A6: 46063 | B6: Chứng từ chi tiền sinh nhật quý 1/2026 + 02/2026 | C6: 9600000
A7: 46063 | B7: Chi tiền thanh toán lễ thăm viếng | C7: 1000000 | D7: Ngô Minh Hòa | E7: Nguyễn Minh Cường | G7: Bác bị mất ngày 14/11/2025 | H7: Lê Anh Tuấn | I7: Phú Thọ
A8: 46063 | B8: Chi thăm hỏi đồng chí Bùi Văn Tình | C8: 500000 | D8: Bùi Văn Tình | E8: Bùi Văn Tình | G8: Ốm Đi viện | H8: Bùi Văn Tình | I8: Hòa Bình
A9: 46063 | B9: Thăm hỏi đoàn viên công đoàn | C9: 500000 | D9: Trần Đức Tân | E9: Trần Tuyên | G9: Ốm Đi viện | H9: Lê Anh Tuấn | I9: Phú Thọ
A10: 46063 | B10: Thăm hỏi đoàn viên công đoàn | C10: 500000 | D10: Nguyễn Đắc Thao | E10: Nguyễn Mạnh Cường | G10: Ốm Đi viện | H10: Lê Anh Tuấn | I10: Phú Thọ
A11: 46091 | B11: Thăm hỏi đoàn viên công đoàn | C11: 300000 | D11: Nguyễn Thị Hồng Vân | E11: Ôn Đức Phương | F11: Vợ | G11: Sinh em bé | H11: Nguyễn Văn Phây | I11: Vĩnh phúc
A12: 46091 | B12: Thăm hỏi đoàn viên công đoàn | C12: 300000 | D12: Nguyễn Thị Thanh Hải | E12: Cao Văn Huy | F12: Vợ | G12: Sinh em bé | H12: Nguyễn Văn Phây | I12: Vĩnh phúc
A13: 46091 | B13: Chi tiền thanh toán lễ thăm viếng | C13: 1000000 | D13: Đỗ Thị Niên | E13: Trần Anh Quân | G13: Bác bị mất ngày 26/1/2026 | H13: Nguyễn Văn Phây | I13: Vĩnh phúc
A14: 46091 | B14: Thăm hỏi đoàn viên công đoàn | C14: 500000 | D14: Nguyễn Thị Phương Anh | E14: Nguyễn Thị Phương Anh | G14: Ốm Đi viện | H14: Ngô Thị Anh
A15: 46091 | B15: Chi tiền thanh toán lễ thăm viếng | C15: 500000 | D15: Ma Văn Tuất | E15: Ma Văn Nam | F15: Bố đẻ | G15: Bác bị mất ngày 18/2/2026 | H15: Lê Anh Tuấn | I15: Phú Thọ | J15: TTVT Thanh Thủy
A16: 46091 | B16: Chi tiền thanh toán lễ thăm viếng | C16: 1000000 | D16: Đinh Thị Vân | E16: Ngô Anh Đức | F16: Mẹ vợ | G16: Bác bị mất ngày 28/2/2026 | H16: Ngô Thị Anh | J16: VNPT Vĩnh Tường
A17: 46091 | B17: Thăm hỏi đoàn viên công đoàn | C17: 500000 | D17: Bùi Văn Xuân | E17: Bùi Văn Đông | F17: Bố | G17: Ốm Đi viện | H17: Dương Văn Nam | I17: Hòa Bình
A18: 46091 | B18: Thăm hỏi đoàn viên công đoàn | C18: 500000 | D18: Nguyễn Trường Sơn | E18: Nguyễn Trường Sơn | G18: Ốm Đi viện | H18: Dương Văn Nam | I18: Hòa Bình
A19: 46091 | B19: Thăm hỏi đoàn viên công đoàn | C19: 500000 | D19: Bùi Văn Lệch | E19: Bùi Văn Nhất | G19: Ốm Đi viện | H19: Dương Văn Nam | I19: Hòa Bình
A20: 46091 | B20: Thăm hỏi đoàn viên công đoàn | C20: 300000 | D20: Đường Thị Ngọc Trang | E20: Nguyễn Tuấn Linh | F20: Vợ | G20: Sinh em bé | H20: Nguyễn Văn Phây | I20: Vĩnh phúc
A21: 46104 | B21: Thăm hỏi đoàn viên công đoàn | C21: 500000 | D21: Nguyễn Bảo Ngọc | E21: Hoàng Phương Nhung | F21: Con gái | G21: Ốm Đi viện | H21: Nguyễn Văn Phây | I21: Vĩnh phúc
A22: 46104 | B22: Chi tiền thanh toán lễ thăm viếng | C22: 1000000 | D22: Nguyễn Văn Hồng | E22: Nguyễn Văn Quân | F22: Bố đẻ | G22: Bác bị mất ngày 20/03/2026 | H22: Nguyễn Văn Phây | I22: Vĩnh phúc | J22: TTVT Vĩnh Tường
A23: 46104 | B23: Thăm hỏi đoàn viên công đoàn | C23: 500000 | D23: Lê Quân Nhạc | E23: Bùi Thanh Quang | F23: Bố vợ | G23: Ốm Đi viện | H23: Dương Văn Nam | I23: Hòa Bình
A24: 46104 | B24: Thăm hỏi đoàn viên công đoàn | C24: 500000 | D24: Hoàng Trung Quân | E24: Hoàng Trung Dũng | G24: Ốm Đi viện | H24: Dương Văn Nam | I24: Hòa Bình
A25: 46119 | B25: Thăm hỏi đoàn viên công đoàn | C25: 500000 | D25: Tăng Bá Trứ | E25: Nguyễn Thị Ánh Tuyết | F25: bố | G25: Ốm Đi viện | H25: Dương Văn Nam | I25: Hòa Bình
A26: 46119 | B26: Thăm hỏi đoàn viên công đoàn | C26: 500000 | D26: Nguyễn Thị Thanh Tuyết | E26: Hoàng Xuân Sửu | F26: vợ | G26: Ốm Đi viện | H26: Nguyễn Văn Phây | I26: Vĩnh phúc
A27: 46126 | B27: Chi tiền sinh nhật tháng 03/2026 | C27: 4500000
A28: 46126 | B28: Chi tiền thăm hỏi đoàn viên công đoàn | C28: 300000 | D28: Bùi Văn Nhất | E28: Bùi Văn Nhất | F28: đồng chí | G28: Ốm Đi viện | H28: Dương Văn Nam | I28: Hòa Bình
A29: 46128 | B29: Chi tiền thăm hỏi đoàn viên công đoàn | C29: 300000 | D29: Nguyễn Thị Phương | E29: Nguyễn Minh Chí | F29: vợ | G29: Ốm Đi viện | H29: Nguyễn Văn Phây | I29: Vĩnh phúc
A30: 46128 | B30: Chi tiền thăm hỏi đoàn viên công đoàn | C30: 300000 | D30: Hạ Thị Ái | E30: Đặng Hồng Quân | F30: Mẹ vợ | G30: Ốm Đi viện | H30: Lê Anh Tuấn | I30: Phú Thọ
A31: 46134 | B31: Chi tiền sinh nhật tháng 04/2026 CĐ TT Hạ tầng | C31: 3400000
A32: 46149 | B32: Chi tiền thanh toán lễ thăm viếng | C32: 1000000 | D32: Phùng Minh Gióng | E32: Phùng Thế Nam | F32: bố | G32: Mất | H32: Dương Văn Nam | I32: Hòa Bình
A33: 46149 | B33: Chi tiền thăm hỏi đoàn viên công đoàn | C33: 300000 | D33: Vũ Thị Thảo | E33: Nguyễn Hữu Ước | F33: vợ | G33: Ốm Đi viện | H33: Nguyễn Văn Phây | I33: Vĩnh phúc
A34: 46154 | B34: QĐ số 19 ngày 28/04/2026 Trợ cấp đoàn viên gặp hoả hoạn tai nạn rủi ro | C34: 7000000
A35: 46154 | B35: Chi tiền thăm hỏi đoàn viên công đoàn | C35: 300000 | D35: Nguyễn Minh Chí | E35: Nguyễn Minh Chí | G35: Ốm Đi viện | H35: Nguyễn Văn Phây | I35: Vĩnh phúc
A36: 46154 | B36: Chi tiền thăm hỏi đoàn viên công đoàn | C36: 300000 | D36: Hà Văn Huẩn | E36: Hà Văn Huẩn | G36: Ốm Đi viện | H36: Dương Văn Nam | I36: Hòa Bình
A37: 46163 | B37: Chi tiền thanh toán lễ thăm viếng | C37: 1000000 | D37: Quách Văn Khái | E37: Nguyễn Minh Trí | F37: bố | G37: Mất | H37: Lê Anh Tuấn | I37: Phú Thọ
A38: 46182 | B38: Chi sinh nhật T5 CĐ TT Hạ tầng | C38: 2800000
A39: 46182 | B39: Chi tiền thăm hỏi đoàn viên công đoàn | C39: 300000 | D39: Đồng Thị Loan | E39: Lê Thế Long | F39: vợ | G39: Sinh em bé | H39: Nguyễn Văn Phây | I39: Vĩnh phúc
A40: 46182 | B40: Chi tiền thăm hỏi đoàn viên công đoàn | C40: 300000 | D40: Vũ Thị Lan Phương | E40: Vũ Thị Lan Phương | G40: tai nạn bất ngờ | H40: Lê Anh Tuấn | I40: Phú Thọ
...

Sheet HUONG_DAN
A1: HỆ THỐNG CÔNG ĐOÀN SỐ Quản lý công tác chăm lo đoàn viên, người lao động
A4: MỤC | B4: NỘI DUNG
A5: 1. TIEP_NHAN | B5: Các Tổ Hạ tầng nhập trường hợp mới phát sinh. Cột màu vàng là cột cần nhập; các cột còn lại dùng để theo dõi tiến độ.
A6: 2. DL_CHAM_LO | B6: Cơ sở dữ liệu lịch sử và phát sinh đã được chuẩn hóa. Dữ liệu gốc vẫn được giữ nguyên tại sheet TH.
A7: 3. QUY_CHE | B7: Danh mục loại chăm lo, mức hỗ trợ tham khảo và hồ sơ cần có. Ban Chấp hành Công đoàn là cấp quyết định cuối cùng.
A8: 4. DASHBOARD | B8: Theo dõi nhanh tổng số lượt, tổng kinh phí, cơ cấu loại hỗ trợ, địa bàn và trạng thái xử lý.
A9: 5. AI_TRO_LY | B9: Tạo nội dung đầu vào để sử dụng với công cụ AI: phân loại vụ việc, kiểm tra hồ sơ, soạn tờ trình, quyết định, danh sách chi và báo cáo.
A10: Quy trình | B10: Tổ nhập thông tin → Cán bộ công đoàn kiểm tra → Đối chiếu quy chế → Trình duyệt → Chi trả → Hoàn thiện chứng từ → Lưu hồ sơ số.
A11: Nguyên tắc bảo mật | B11: Không đưa CCCD, số tài khoản, hồ sơ bệnh án hoặc dữ liệu cá nhân nhạy cảm lên công cụ AI công cộng. Chỉ dùng dữ liệu tối thiểu cần thiết và phải kiểm tra lại kết quả AI.

Sheet DL_CHAM_LO
A1: Mã hồ sơ | B1: Ngày phát sinh | C1: Năm | D1: Tháng | E1: Nội dung | F1: Loại chăm lo | G1: Số tiền | H1: Người được thăm/hỗ trợ | I1: Đoàn viên liên quan | J1: Quan hệ | K1: Lý do | L1: Người thực hiện | M1: Địa bàn | N1: Đơn vị | O1: Trạng thái | P1: Ngày hoàn thành | Q1: Số ngày xử lý | R1: Cảnh báo
A2: LS-001 | B2: 46048 | C2: =YEAR(B2) -> 2026 | D2: =MONTH(B2) -> 1 | E2: Chi tiền viếng bố đẻ đc Lò Văn Sơn – CĐ Hạ tấng | F2: Hiếu/viếng | G2: 800000 | I2: Lò Văn Sơn | K2: Mất | O2: Đã hoàn thành | P2: 46048 | Q2: =IF(OR(B2="",P2=""),"",P2-B2) -> 0 | R2: =IF(O2<>"Đã hoàn thành","Chưa hoàn thành",IF(Q2>5,"Xử lý chậm","Đúng hạn")) -> Đúng hạn
A3: LS-002 | B3: 46055 | C3: =YEAR(B3) -> 2026 | D3: =MONTH(B3) -> 2 | E3: Chi tiền tặng quà ĐVCĐ nghỉ việc CĐ TT Hạ tầng | F3: Quà đoàn viên nghỉ việc | G3: 2500000 | O3: Đã hoàn thành | P3: 46055 | Q3: =IF(OR(B3="",P3=""),"",P3-B3) -> 0 | R3: =IF(O3<>"Đã hoàn thành","Chưa hoàn thành",IF(Q3>5,"Xử lý chậm","Đúng hạn")) -> Đúng hạn
A4: LS-003 | B4: 46066 | C4: =YEAR(B4) -> 2026 | D4: =MONTH(B4) -> 2 | E4: Chi tien tham vo dc Tuan sinh con CD TT Ha tang | F4: Hỷ/Sinh con | G4: 300000 | I4: Đồng chí Tuấn | O4: Đã hoàn thành | P4: 46066 | Q4: =IF(OR(B4="",P4=""),"",P4-B4) -> 0 | R4: =IF(O4<>"Đã hoàn thành","Chưa hoàn thành",IF(Q4>5,"Xử lý chậm","Đúng hạn")) -> Đúng hạn
A5: LS-004 | B5: 46063 | C5: =YEAR(B5) -> 2026 | D5: =MONTH(B5) -> 2 | E5: Chứng từ chi tiền sinh nhật quý 4/2025 | F5: Sinh nhật | G5: 14100000 | O5: Đã hoàn thành | P5: 46063 | Q5: =IF(OR(B5="",P5=""),"",P5-B5) -> 0 | R5: =IF(O5<>"Đã hoàn thành","Chưa hoàn thành",IF(Q5>5,"Xử lý chậm","Đúng hạn")) -> Đúng hạn
A6: LS-005 | B6: 46063 | C6: =YEAR(B6) -> 2026 | D6: =MONTH(B6) -> 2 | E6: Chứng từ chi tiền sinh nhật quý 1/2026 + 02/2026 | F6: Sinh nhật | G6: 9600000 | O6: Đã hoàn thành | P6: 46063 | Q6: =IF(OR(B6="",P6=""),"",P6-B6) -> 0 | R6: =IF(O6<>"Đã hoàn thành","Chưa hoàn thành",IF(Q6>5,"Xử lý chậm","Đúng hạn")) -> Đúng hạn
A7: LS-006 | B7: 46063 | C7: =YEAR(B7) -> 2026 | D7: =MONTH(B7) -> 2 | E7: Chi tiền thanh toán lễ thăm viếng | F7: Hiếu/viếng | G7: 1000000 | H7: Ngô Minh Hòa | I7: Nguyễn Minh Cường | K7: Bác bị mất ngày 14/11/2025 | L7: Lê Anh Tuấn | M7: Phú Thọ | O7: Đã hoàn thành | P7: 46063 | Q7: =IF(OR(B7="",P7=""),"",P7-B7) -> 0 | R7: =IF(O7<>"Đã hoàn thành","Chưa hoàn thành",IF(Q7>5,"Xử lý chậm","Đúng hạn")) -> Đúng hạn
A8: LS-007 | B8: 46063 | C8: =YEAR(B8) -> 2026 | D8: =MONTH(B8) -> 2 | E8: Chi thăm hỏi đồng chí Bùi Văn Tình | F8: Ốm đau/đi viện | G8: 500000 | H8: Bùi Văn Tình | I8: Bùi Văn Tình | K8: Ốm Đi viện | L8: Bùi Văn Tình | M8: Hòa Bình | O8: Đã hoàn thành | P8: 46063 | Q8: =IF(OR(B8="",P8=""),"",P8-B8) -> 0 | R8: =IF(O8<>"Đã hoàn thành","Chưa hoàn thành",IF(Q8>5,"Xử lý chậm","Đúng hạn")) -> Đúng hạn
A9: LS-008 | B9: 46063 | C9: =YEAR(B9) -> 2026 | D9: =MONTH(B9) -> 2 | E9: Thăm hỏi đoàn viên công đoàn | F9: Ốm đau/đi viện | G9: 500000 | H9: Trần Đức Tân | I9: Trần Tuyên | K9: Ốm Đi viện | L9: Lê Anh Tuấn | M9: Phú Thọ | O9: Đã hoàn thành | P9: 46063 | Q9: =IF(OR(B9="",P9=""),"",P9-B9) -> 0 | R9: =IF(O9<>"Đã hoàn thành","Chưa hoàn thành",IF(Q9>5,"Xử lý chậm","Đúng hạn")) -> Đúng hạn
A10: LS-009 | B10: 46063 | C10: =YEAR(B10) -> 2026 | D10: =MONTH(B10) -> 2 | E10: Thăm hỏi đoàn viên công đoàn | F10: Ốm đau/đi viện | G10: 500000 | H10: Nguyễn Đắc Thao | I10: Nguyễn Mạnh Cường | K10: Ốm Đi viện | L10: Lê Anh Tuấn | M10: Phú Thọ | O10: Đã hoàn thành | P10: 46063 | Q10: =IF(OR(B10="",P10=""),"",P10-B10) -> 0 | R10: =IF(O10<>"Đã hoàn thành","Chưa hoàn thành",IF(Q10>5,"Xử lý chậm","Đúng hạn")) -> Đúng hạn
A11: LS-010 | B11: 46091 | C11: =YEAR(B11) -> 2026 | D11: =MONTH(B11) -> 3 | E11: Thăm hỏi đoàn viên công đoàn | F11: Hỷ/Sinh con | G11: 300000 | H11: Nguyễn Thị Hồng Vân | I11: Ôn Đức Phương | J11: Vợ | K11: Sinh em bé | L11: Nguyễn Văn Phây | M11: Vĩnh phúc | O11: Đã hoàn thành | P11: 46091 | Q11: =IF(OR(B11="",P11=""),"",P11-B11) -> 0 | R11: =IF(O11<>"Đã hoàn thành","Chưa hoàn thành",IF(Q11>5,"Xử lý chậm","Đúng hạn")) -> Đúng hạn
A12: LS-011 | B12: 46091 | C12: =YEAR(B12) -> 2026 | D12: =MONTH(B12) -> 3 | E12: Thăm hỏi đoàn viên công đoàn | F12: Hỷ/Sinh con | G12: 300000 | H12: Nguyễn Thị Thanh Hải | I12: Cao Văn Huy | J12: Vợ | K12: Sinh em bé | L12: Nguyễn Văn Phây | M12: Vĩnh phúc | O12: Đã hoàn thành | P12: 46091 | Q12: =IF(OR(B12="",P12=""),"",P12-B12) -> 0 | R12: =IF(O12<>"Đã hoàn thành","Chưa hoàn thành",IF(Q12>5,"Xử lý chậm","Đúng hạn")) -> Đúng hạn
A13: LS-012 | B13: 46091 | C13: =YEAR(B13) -> 2026 | D13: =MONTH(B13) -> 3 | E13: Chi tiền thanh toán lễ thăm viếng | F13: Hiếu/viếng | G13: 1000000 | H13: Đỗ Thị Niên | I13: Trần Anh Quân | K13: Bác bị mất ngày 26/1/2026 | L13: Nguyễn Văn Phây | M13: Vĩnh phúc | O13: Đã hoàn thành | P13: 46091 | Q13: =IF(OR(B13="",P13=""),"",P13-B13) -> 0 | R13: =IF(O13<>"Đã hoàn thành","Chưa hoàn thành",IF(Q13>5,"Xử lý chậm","Đúng hạn")) -> Đúng hạn
A14: LS-013 | B14: 46091 | C14: =YEAR(B14) -> 2026 | D14: =MONTH(B14) -> 3 | E14: Thăm hỏi đoàn viên công đoàn | F14: Ốm đau/đi viện | G14: 500000 | H14: Nguyễn Thị Phương Anh | I14: Nguyễn Thị Phương Anh | K14: Ốm Đi viện | L14: Ngô Thị Anh | O14: Đã hoàn thành | P14: 46091 | Q14: =IF(OR(B14="",P14=""),"",P14-B14) -> 0 | R14: =IF(O14<>"Đã hoàn thành","Chưa hoàn thành",IF(Q14>5,"Xử lý chậm","Đúng hạn")) -> Đúng hạn
A15: LS-014 | B15: 46091 | C15: =YEAR(B15) -> 2026 | D15: =MONTH(B15) -> 3 | E15: Chi tiền thanh toán lễ thăm viếng | F15: Hiếu/viếng | G15: 500000 | H15: Ma Văn Tuất | I15: Ma Văn Nam | J15: Bố đẻ | K15: Bác bị mất ngày 18/2/2026 | L15: Lê Anh Tuấn | M15: Phú Thọ | N15: TTVT Thanh Thủy | O15: Đã hoàn thành | P15: 46091 | Q15: =IF(OR(B15="",P15=""),"",P15-B15) -> 0 | R15: =IF(O15<>"Đã hoàn thành","Chưa hoàn thành",IF(Q15>5,"Xử lý chậm","Đúng hạn")) -> Đúng hạn
A16: LS-015 | B16: 46091 | C16: =YEAR(B16) -> 2026 | D16: =MONTH(B16) -> 3 | E16: Chi tiền thanh toán lễ thăm viếng | F16: Hiếu/viếng | G16: 1000000 | H16: Đinh Thị Vân | I16: Ngô Anh Đức | J16: Mẹ vợ | K16: Bác bị mất ngày 28/2/2026 | L16: Ngô Thị Anh | N16: VNPT Vĩnh Tường | O16: Đã hoàn thành | P16: 46091 | Q16: =IF(OR(B16="",P16=""),"",P16-B16) -> 0 | R16: =IF(O16<>"Đã hoàn thành","Chưa hoàn thành",IF(Q16>5,"Xử lý chậm","Đúng hạn")) -> Đúng hạn
A17: LS-016 | B17: 46091 | C17: =YEAR(B17) -> 2026 | D17: =MONTH(B17) -> 3 | E17: Thăm hỏi đoàn viên công đoàn | F17: Ốm đau/đi viện | G17: 500000 | H17: Bùi Văn Xuân | I17: Bùi Văn Đông | J17: Bố | K17: Ốm Đi viện | L17: Dương Văn Nam | M17: Hòa Bình | O17: Đã hoàn thành | P17: 46091 | Q17: =IF(OR(B17="",P17=""),"",P17-B17) -> 0 | R17: =IF(O17<>"Đã hoàn thành","Chưa hoàn thành",IF(Q17>5,"Xử lý chậm","Đúng hạn")) -> Đúng hạn
A18: LS-017 | B18: 46091 | C18: =YEAR(B18) -> 2026 | D18: =MONTH(B18) -> 3 | E18: Thăm hỏi đoàn viên công đoàn | F18: Ốm đau/đi viện | G18: 500000 | H18: Nguyễn Trường Sơn | I18: Nguyễn Trường Sơn | K18: Ốm Đi viện | L18: Dương Văn Nam | M18: Hòa Bình | O18: Đã hoàn thành | P18: 46091 | Q18: =IF(OR(B18="",P18=""),"",P18-B18) -> 0 | R18: =IF(O18<>"Đã hoàn thành","Chưa hoàn thành",IF(Q18>5,"Xử lý chậm","Đúng hạn")) -> Đúng hạn
A19: LS-018 | B19: 46091 | C19: =YEAR(B19) -> 2026 | D19: =MONTH(B19) -> 3 | E19: Thăm hỏi đoàn viên công đoàn | F19: Ốm đau/đi viện | G19: 500000 | H19: Bùi Văn Lệch | I19: Bùi Văn Nhất | K19: Ốm Đi viện | L19: Dương Văn Nam | M19: Hòa Bình | O19: Đã hoàn thành | P19: 46091 | Q19: =IF(OR(B19="",P19=""),"",P19-B19) -> 0 | R19: =IF(O19<>"Đã hoàn thành","Chưa hoàn thành",IF(Q19>5,"Xử lý chậm","Đúng hạn")) -> Đúng hạn
A20: LS-019 | B20: 46091 | C20: =YEAR(B20) -> 2026 | D20: =MONTH(B20) -> 3 | E20: Thăm hỏi đoàn viên công đoàn | F20: Hỷ/Sinh con | G20: 300000 | H20: Đường Thị Ngọc Trang | I20: Nguyễn Tuấn Linh | J20: Vợ | K20: Sinh em bé | L20: Nguyễn Văn Phây | M20: Vĩnh phúc | O20: Đã hoàn thành | P20: 46091 | Q20: =IF(OR(B20="",P20=""),"",P20-B20) -> 0 | R20: =IF(O20<>"Đã hoàn thành","Chưa hoàn thành",IF(Q20>5,"Xử lý chậm","Đúng hạn")) -> Đúng hạn
A21: LS-020 | B21: 46104 | C21: =YEAR(B21) -> 2026 | D21: =MONTH(B21) -> 3 | E21: Thăm hỏi đoàn viên công đoàn | F21: Ốm đau/đi viện | G21: 500000 | H21: Nguyễn Bảo Ngọc | I21: Hoàng Phương Nhung | J21: Con gái | K21: Ốm Đi viện | L21: Nguyễn Văn Phây | M21: Vĩnh phúc | O21: Đã hoàn thành | P21: 46104 | Q21: =IF(OR(B21="",P21=""),"",P21-B21) -> 0 | R21: =IF(O21<>"Đã hoàn thành","Chưa hoàn thành",IF(Q21>5,"Xử lý chậm","Đúng hạn")) -> Đúng hạn
A22: LS-021 | B22: 46104 | C22: =YEAR(B22) -> 2026 | D22: =MONTH(B22) -> 3 | E22: Chi tiền thanh toán lễ thăm viếng | F22: Hiếu/viếng | G22: 1000000 | H22: Nguyễn Văn Hồng | I22: Nguyễn Văn Quân | J22: Bố đẻ | K22: Bác bị mất ngày 20/03/2026 | L22: Nguyễn Văn Phây | M22: Vĩnh phúc | N22: TTVT Vĩnh Tường | O22: Đã hoàn thành | P22: 46104 | Q22: =IF(OR(B22="",P22=""),"",P22-B22) -> 0 | R22: =IF(O22<>"Đã hoàn thành","Chưa hoàn thành",IF(Q22>5,"Xử lý chậm","Đúng hạn")) -> Đúng hạn
A23: LS-022 | B23: 46104 | C23: =YEAR(B23) -> 2026 | D23: =MONTH(B23) -> 3 | E23: Thăm hỏi đoàn viên công đoàn | F23: Ốm đau/đi viện | G23: 500000 | H23: Lê Quân Nhạc | I23: Bùi Thanh Quang | J23: Bố vợ | K23: Ốm Đi viện | L23: Dương Văn Nam | M23: Hòa Bình | O23: Đã hoàn thành | P23: 46104 | Q23: =IF(OR(B23="",P23=""),"",P23-B23) -> 0 | R23: =IF(O23<>"Đã hoàn thành","Chưa hoàn thành",IF(Q23>5,"Xử lý chậm","Đúng hạn")) -> Đúng hạn
A24: LS-023 | B24: 46104 | C24: =YEAR(B24) -> 2026 | D24: =MONTH(B24) -> 3 | E24: Thăm hỏi đoàn viên công đoàn | F24: Ốm đau/đi viện | G24: 500000 | H24: Hoàng Trung Quân | I24: Hoàng Trung Dũng | K24: Ốm Đi viện | L24: Dương Văn Nam | M24: Hòa Bình | O24: Đã hoàn thành | P24: 46104 | Q24: =IF(OR(B24="",P24=""),"",P24-B24) -> 0 | R24: =IF(O24<>"Đã hoàn thành","Chưa hoàn thành",IF(Q24>5,"Xử lý chậm","Đúng hạn")) -> Đúng hạn
A25: LS-024 | B25: 46119 | C25: =YEAR(B25) -> 2026 | D25: =MONTH(B25) -> 4 | E25: Thăm hỏi đoàn viên công đoàn | F25: Ốm đau/đi viện | G25: 500000 | H25: Tăng Bá Trứ | I25: Nguyễn Thị Ánh Tuyết | J25: bố | K25: Ốm Đi viện | L25: Dương Văn Nam | M25: Hòa Bình | O25: Đã hoàn thành | P25: 46119 | Q25: =IF(OR(B25="",P25=""),"",P25-B25) -> 0 | R25: =IF(O25<>"Đã hoàn thành","Chưa hoàn thành",IF(Q25>5,"Xử lý chậm","Đúng hạn")) -> Đúng hạn
A26: LS-025 | B26: 46119 | C26: =YEAR(B26) -> 2026 | D26: =MONTH(B26) -> 4 | E26: Thăm hỏi đoàn viên công đoàn | F26: Ốm đau/đi viện | G26: 500000 | H26: Nguyễn Thị Thanh Tuyết | I26: Hoàng Xuân Sửu | J26: vợ | K26: Ốm Đi viện | L26: Nguyễn Văn Phây | M26: Vĩnh phúc | O26: Đã hoàn thành | P26: 46119 | Q26: =IF(OR(B26="",P26=""),"",P26-B26) -> 0 | R26: =IF(O26<>"Đã hoàn thành","Chưa hoàn thành",IF(Q26>5,"Xử lý chậm","Đúng hạn")) -> Đúng hạn
A27: LS-026 | B27: 46126 | C27: =YEAR(B27) -> 2026 | D27: =MONTH(B27) -> 4 | E27: Chi tiền sinh nhật tháng 03/2026 | F27: Sinh nhật | G27: 4500000 | O27: Đã hoàn thành | P27: 46126 | Q27: =IF(OR(B27="",P27=""),"",P27-B27) -> 0 | R27: =IF(O27<>"Đã hoàn thành","Chưa hoàn thành",IF(Q27>5,"Xử lý chậm","Đúng hạn")) -> Đúng hạn
A28: LS-027 | B28: 46126 | C28: =YEAR(B28) -> 2026 | D28: =MONTH(B28) -> 4 | E28: Chi tiền thăm hỏi đoàn viên công đoàn | F28: Ốm đau/đi viện | G28: 300000 | H28: Bùi Văn Nhất | I28: Bùi Văn Nhất | J28: đồng chí | K28: Ốm Đi viện | L28: Dương Văn Nam | M28: Hòa Bình | O28: Đã hoàn thành | P28: 46126 | Q28: =IF(OR(B28="",P28=""),"",P28-B28) -> 0 | R28: =IF(O28<>"Đã hoàn thành","Chưa hoàn thành",IF(Q28>5,"Xử lý chậm","Đúng hạn")) -> Đúng hạn
A29: LS-028 | B29: 46128 | C29: =YEAR(B29) -> 2026 | D29: =MONTH(B29) -> 4 | E29: Chi tiền thăm hỏi đoàn viên công đoàn | F29: Ốm đau/đi viện | G29: 300000 | H29: Nguyễn Thị Phương | I29: Nguyễn Minh Chí | J29: vợ | K29: Ốm Đi viện | L29: Nguyễn Văn Phây | M29: Vĩnh phúc | O29: Đã hoàn thành | P29: 46128 | Q29: =IF(OR(B29="",P29=""),"",P29-B29) -> 0 | R29: =IF(O29<>"Đã hoàn thành","Chưa hoàn thành",IF(Q29>5,"Xử lý chậm","Đúng hạn")) -> Đúng hạn
A30: LS-029 | B30: 46128 | C30: =YEAR(B30) -> 2026 | D30: =MONTH(B30) -> 4 | E30: Chi tiền thăm hỏi đoàn viên công đoàn | F30: Ốm đau/đi viện | G30: 300000 | H30: Hạ Thị Ái | I30: Đặng Hồng Quân | J30: Mẹ vợ | K30: Ốm Đi viện | L30: Lê Anh Tuấn | M30: Phú Thọ | O30: Đã hoàn thành | P30: 46128 | Q30: =IF(OR(B30="",P30=""),"",P30-B30) -> 0 | R30: =IF(O30<>"Đã hoàn thành","Chưa hoàn thành",IF(Q30>5,"Xử lý chậm","Đúng hạn")) -> Đúng hạn
A31: LS-030 | B31: 46134 | C31: =YEAR(B31) -> 2026 | D31: =MONTH(B31) -> 4 | E31: Chi tiền sinh nhật tháng 04/2026 CĐ TT Hạ tầng | F31: Sinh nhật | G31: 3400000 | O31: Đã hoàn thành | P31: 46134 | Q31: =IF(OR(B31="",P31=""),"",P31-B31) -> 0 | R31: =IF(O31<>"Đã hoàn thành","Chưa hoàn thành",IF(Q31>5,"Xử lý chậm","Đúng hạn")) -> Đúng hạn
A32: LS-031 | B32: 46149 | C32: =YEAR(B32) -> 2026 | D32: =MONTH(B32) -> 5 | E32: Chi tiền thanh toán lễ thăm viếng | F32: Hiếu/viếng | G32: 1000000 | H32: Phùng Minh Gióng | I32: Phùng Thế Nam | J32: bố | K32: Mất | L32: Dương Văn Nam | M32: Hòa Bình | O32: Đã hoàn thành | P32: 46149 | Q32: =IF(OR(B32="",P32=""),"",P32-B32) -> 0 | R32: =IF(O32<>"Đã hoàn thành","Chưa hoàn thành",IF(Q32>5,"Xử lý chậm","Đúng hạn")) -> Đúng hạn
A33: LS-032 | B33: 46149 | C33: =YEAR(B33) -> 2026 | D33: =MONTH(B33) -> 5 | E33: Chi tiền thăm hỏi đoàn viên công đoàn | F33: Ốm đau/đi viện | G33: 300000 | H33: Vũ Thị Thảo | I33: Nguyễn Hữu Ước | J33: vợ | K33: Ốm Đi viện | L33: Nguyễn Văn Phây | M33: Vĩnh phúc | O33: Đã hoàn thành | P33: 46149 | Q33: =IF(OR(B33="",P33=""),"",P33-B33) -> 0 | R33: =IF(O33<>"Đã hoàn thành","Chưa hoàn thành",IF(Q33>5,"Xử lý chậm","Đúng hạn")) -> Đúng hạn
A34: LS-033 | B34: 46154 | C34: =YEAR(B34) -> 2026 | D34: =MONTH(B34) -> 5 | E34: QĐ số 19 ngày 28/04/2026 Trợ cấp đoàn viên gặp hoả hoạn tai nạn rủi ro | F34: Tai nạn/rủi ro | G34: 7000000 | O34: Đã hoàn thành | P34: 46154 | Q34: =IF(OR(B34="",P34=""),"",P34-B34) -> 0 | R34: =IF(O34<>"Đã hoàn thành","Chưa hoàn thành",IF(Q34>5,"Xử lý chậm","Đúng hạn")) -> Đúng hạn
A35: LS-034 | B35: 46154 | C35: =YEAR(B35) -> 2026 | D35: =MONTH(B35) -> 5 | E35: Chi tiền thăm hỏi đoàn viên công đoàn | F35: Ốm đau/đi viện | G35: 300000 | H35: Nguyễn Minh Chí | I35: Nguyễn Minh Chí | K35: Ốm Đi viện | L35: Nguyễn Văn Phây | M35: Vĩnh phúc | O35: Đã hoàn thành | P35: 46154 | Q35: =IF(OR(B35="",P35=""),"",P35-B35) -> 0 | R35: =IF(O35<>"Đã hoàn thành","Chưa hoàn thành",IF(Q35>5,"Xử lý chậm","Đúng hạn")) -> Đúng hạn
A36: LS-035 | B36: 46154 | C36: =YEAR(B36) -> 2026 | D36: =MONTH(B36) -> 5 | E36: Chi tiền thăm hỏi đoàn viên công đoàn | F36: Ốm đau/đi viện | G36: 300000 | H36: Hà Văn Huẩn | I36: Hà Văn Huẩn | K36: Ốm Đi viện | L36: Dương Văn Nam | M36: Hòa Bình | O36: Đã hoàn thành | P36: 46154 | Q36: =IF(OR(B36="",P36=""),"",P36-B36) -> 0 | R36: =IF(O36<>"Đã hoàn thành","Chưa hoàn thành",IF(Q36>5,"Xử lý chậm","Đúng hạn")) -> Đúng hạn
A37: LS-036 | B37: 46163 | C37: =YEAR(B37) -> 2026 | D37: =MONTH(B37) -> 5 | E37: Chi tiền thanh toán lễ thăm viếng | F37: Hiếu/viếng | G37: 1000000 | H37: Quách Văn Khái | I37: Nguyễn Minh Trí | J37: bố | K37: Mất | L37: Lê Anh Tuấn | M37: Phú Thọ | O37: Đã hoàn thành | P37: 46163 | Q37: =IF(OR(B37="",P37=""),"",P37-B37) -> 0 | R37: =IF(O37<>"Đã hoàn thành","Chưa hoàn thành",IF(Q37>5,"Xử lý chậm","Đúng hạn")) -> Đúng hạn
A38: LS-037 | B38: 46182 | C38: =YEAR(B38) -> 2026 | D38: =MONTH(B38) -> 6 | E38: Chi sinh nhật T5 CĐ TT Hạ tầng | F38: Sinh nhật | G38: 2800000 | O38: Đã hoàn thành | P38: 46182 | Q38: =IF(OR(B38="",P38=""),"",P38-B38) -> 0 | R38: =IF(O38<>"Đã hoàn thành","Chưa hoàn thành",IF(Q38>5,"Xử lý chậm","Đúng hạn")) -> Đúng hạn
A39: LS-038 | B39: 46182 | C39: =YEAR(B39) -> 2026 | D39: =MONTH(B39) -> 6 | E39: Chi tiền thăm hỏi đoàn viên công đoàn | F39: Hỷ/Sinh con | G39: 300000 | H39: Đồng Thị Loan | I39: Lê Thế Long | J39: vợ | K39: Sinh em bé | L39: Nguyễn Văn Phây | M39: Vĩnh phúc | O39: Đã hoàn thành | P39: 46182 | Q39: =IF(OR(B39="",P39=""),"",P39-B39) -> 0 | R39: =IF(O39<>"Đã hoàn thành","Chưa hoàn thành",IF(Q39>5,"Xử lý chậm","Đúng hạn")) -> Đúng hạn
A40: LS-039 | B40: 46182 | C40: =YEAR(B40) -> 2026 | D40: =MONTH(B40) -> 6 | E40: Chi tiền thăm hỏi đoàn viên công đoàn | F40: Tai nạn/rủi ro | G40: 300000 | H40: Vũ Thị Lan Phương | I40: Vũ Thị Lan Phương | K40: tai nạn bất ngờ | L40: Lê Anh Tuấn | M40: Phú Thọ | O40: Đã hoàn thành | P40: 46182 | Q40: =IF(OR(B40="",P40=""),"",P40-B40) -> 0 | R40: =IF(O40<>"Đã hoàn thành","Chưa hoàn thành",IF(Q40>5,"Xử lý chậm","Đúng hạn")) -> Đúng hạn
...

Sheet TIEP_NHAN
A1: Mã hồ sơ | B1: Ngày tiếp nhận | C1: Người đề nghị | D1: Tổ/Địa bàn | E1: Đoàn viên liên quan | F1: Người được hỗ trợ | G1: Quan hệ | H1: Nội dung sự việc | I1: Loại chăm lo | J1: Mức đề nghị | K1: Hồ sơ đã có | L1: Hồ sơ còn thiếu | M1: Mức độ ưu tiên | N1: Người xử lý | O1: Hạn xử lý | P1: Trạng thái | Q1: Ngày duyệt | R1: Ngày chi | S1: Kết quả/Ghi chú | T1: Đường dẫn hồ sơ số
A2: =IF(B2="","","HS-"&TEXT(ROW()-4,"000")) | O2: =IF(B2="","",B2+IF(M2="Khẩn cấp",1,IF(M2="Cao",2,5)))
A3: =IF(B3="","","HS-"&TEXT(ROW()-4,"000")) | O3: =IF(B3="","",B3+IF(M3="Khẩn cấp",1,IF(M3="Cao",2,5)))
A4: =IF(B4="","","HS-"&TEXT(ROW()-4,"000")) | O4: =IF(B4="","",B4+IF(M4="Khẩn cấp",1,IF(M4="Cao",2,5)))
A5: =IF(B5="","","HS-"&TEXT(ROW()-4,"000")) | O5: =IF(B5="","",B5+IF(M5="Khẩn cấp",1,IF(M5="Cao",2,5)))
A6: =IF(B6="","","HS-"&TEXT(ROW()-4,"000")) | O6: =IF(B6="","",B6+IF(M6="Khẩn cấp",1,IF(M6="Cao",2,5)))
A7: =IF(B7="","","HS-"&TEXT(ROW()-4,"000")) | O7: =IF(B7="","",B7+IF(M7="Khẩn cấp",1,IF(M7="Cao",2,5)))
A8: =IF(B8="","","HS-"&TEXT(ROW()-4,"000")) | O8: =IF(B8="","",B8+IF(M8="Khẩn cấp",1,IF(M8="Cao",2,5)))
A9: =IF(B9="","","HS-"&TEXT(ROW()-4,"000")) | O9: =IF(B9="","",B9+IF(M9="Khẩn cấp",1,IF(M9="Cao",2,5)))
A10: =IF(B10="","","HS-"&TEXT(ROW()-4,"000")) | O10: =IF(B10="","",B10+IF(M10="Khẩn cấp",1,IF(M10="Cao",2,5)))
A11: =IF(B11="","","HS-"&TEXT(ROW()-4,"000")) | O11: =IF(B11="","",B11+IF(M11="Khẩn cấp",1,IF(M11="Cao",2,5)))
A12: =IF(B12="","","HS-"&TEXT(ROW()-4,"000")) | O12: =IF(B12="","",B12+IF(M12="Khẩn cấp",1,IF(M12="Cao",2,5)))
A13: =IF(B13="","","HS-"&TEXT(ROW()-4,"000")) | O13: =IF(B13="","",B13+IF(M13="Khẩn cấp",1,IF(M13="Cao",2,5)))
... A201: =IF(B201="","","HS-"&TEXT(ROW()-4,"000")) | O201: =IF(B201="","",B201+IF(M201="Khẩn cấp",1,IF(M201="Cao",2,5)))

Sheet QUY_CHE
A1: DANH MỤC CHĂM LO VÀ QUY TẮC XỬ LÝ THAM KHẢO
A4: Mã loại | B4: Loại chăm lo | C4: Từ khóa nhận diện | D4: Mức tham khảo (đồng) | E4: Hồ sơ tối thiểu | F4: Thời hạn xử lý mục tiêu | G4: Ghi chú
A5: OM_DAU | B5: Ốm đau/đi viện | C5: ốm; đi viện; điều trị | D5: 300000 | E5: Đề nghị/Thông tin xác nhận; danh sách chi | F5: 02 ngày | G5: Áp dụng theo quy chế thực tế
A6: HIEU | B6: Hiếu/viếng | C6: mất; viếng; bố; mẹ; vợ; chồng | D6: 1000000 | E6: Thông tin sự việc; danh sách chi; chứng từ | F6: 01 ngày | G6: Mức có thể khác theo quan hệ
A7: HY_SINH_CON | B7: Hỷ/Sinh con | C7: sinh con; sinh em bé | D7: 300000 | E7: Thông tin đoàn viên; danh sách chi | F7: 03 ngày | G7: Theo quy chế thực tế
A8: TAI_NAN_RUI_RO | B8: Tai nạn/rủi ro | C8: tai nạn; hỏa hoạn; rủi ro | D8: 2000000 | E8: Tờ trình; xác minh; quyết định; chứng từ | F8: 01 ngày | G8: Có thể trình trợ cấp bổ sung
A9: SINH_NHAT | B9: Sinh nhật | C9: sinh nhật | D9: 100000 | E9: Danh sách sinh nhật; quyết định/đề nghị chi | F9: Theo tháng | G9: Mức bình quân/người
A10: NGHI_VIEC | B10: Quà đoàn viên nghỉ việc | C10: nghỉ việc; chia tay | D10: 500000 | E10: Danh sách; quyết định/đề nghị chi | F10: 05 ngày | G10: Theo chủ trương từng thời kỳ
A11: KHAC | B11: Khác | C11: khác | D11: 0 | E11: Hồ sơ theo nội dung phát sinh | F11: 05 ngày | G11: BCH xem xét riêng

Sheet DASHBOARD
A1: DASHBOARD CHĂM LO ĐOÀN VIÊN – CÔNG ĐOÀN TRUNG TÂM HẠ TẦNG
A4: TỔNG SỐ LƯỢT | D4: TỔNG KINH PHÍ | G4: SỐ ĐỊA BÀN | J4: MỨC CHI BÌNH QUÂN
A5: =COUNTA(DL_CHAM_LO!A2:A49) -> 48 | D5: =SUM(DL_CHAM_LO!G2:G49) -> 67300000 | G5: =COUNTA(_xludf.UNIQUE(DL_CHAM_LO!M2:M49)) -> 1 | J5: =IFERROR(AVERAGE(DL_CHAM_LO!G2:G49),0) -> 1402083.3
A10: Loại chăm lo | B10: Số lượt | C10: Số tiền | E10: Địa bàn | F10: Số lượt | G10: Số tiền
A11: Ốm đau/đi viện | B11: =COUNTIF(DL_CHAM_LO!F2:F49,A11) -> 24 | C11: =SUMIF(DL_CHAM_LO!F2:F49,A11,DL_CHAM_LO!G2:G49) -> 9600000 | E11: Phú Thọ | F11: =COUNTIF(DL_CHAM_LO!M2:M49,E11) -> 8 | G11: =SUMIF(DL_CHAM_LO!M2:M49,E11,DL_CHAM_LO!G2:G49) -> 4400000
A12: Hiếu/viếng | B12: =COUNTIF(DL_CHAM_LO!F2:F49,A12) -> 8 | C12: =SUMIF(DL_CHAM_LO!F2:F49,A12,DL_CHAM_LO!G2:G49) -> 7300000 | E12: Vĩnh phúc | F12: =COUNTIF(DL_CHAM_LO!M2:M49,E12) -> 15 | G12: =SUMIF(DL_CHAM_LO!M2:M49,E12,DL_CHAM_LO!G2:G49) -> 6300000
A13: Hỷ/Sinh con | B13: =COUNTIF(DL_CHAM_LO!F2:F49,A13) -> 6 | C13: =SUMIF(DL_CHAM_LO!F2:F49,A13,DL_CHAM_LO!G2:G49) -> 1800000 | E13: Hòa Bình | F13: =COUNTIF(DL_CHAM_LO!M2:M49,E13) -> 12 | G13: =SUMIF(DL_CHAM_LO!M2:M49,E13,DL_CHAM_LO!G2:G49) -> 5700000
A14: Tai nạn/rủi ro | B14: =COUNTIF(DL_CHAM_LO!F2:F49,A14) -> 3 | C14: =SUMIF(DL_CHAM_LO!F2:F49,A14,DL_CHAM_LO!G2:G49) -> 9300000 | E14: Chưa xác định | F14: =COUNTBLANK(DL_CHAM_LO!M2:M49) -> 13 | G14: =SUMIF(DL_CHAM_LO!M2:M49,"",DL_CHAM_LO!G2:G49) -> 50900000
A15: Sinh nhật | B15: =COUNTIF(DL_CHAM_LO!F2:F49,A15) -> 6 | C15: =SUMIF(DL_CHAM_LO!F2:F49,A15,DL_CHAM_LO!G2:G49) -> 36800000
A16: Quà đoàn viên nghỉ việc | B16: =COUNTIF(DL_CHAM_LO!F2:F49,A16) -> 1 | C16: =SUMIF(DL_CHAM_LO!F2:F49,A16,DL_CHAM_LO!G2:G49) -> 2500000
A17: Khác | B17: =COUNTIF(DL_CHAM_LO!F2:F49,A17) -> 0 | C17: =SUMIF(DL_CHAM_LO!F2:F49,A17,DL_CHAM_LO!G2:G49) -> 0
A21: Tháng | B21: Số lượt | C21: Số tiền
A22: 1 | B22: =COUNTIFS(DL_CHAM_LO!C2:C49,2026,DL_CHAM_LO!D2:D49,A22) -> 1 | C22: =SUMIFS(DL_CHAM_LO!G2:G49,DL_CHAM_LO!C2:C49,2026,DL_CHAM_LO!D2:D49,A22) -> 800000
A23: 2 | B23: =COUNTIFS(DL_CHAM_LO!C2:C49,2026,DL_CHAM_LO!D2:D49,A23) -> 8 | C23: =SUMIFS(DL_CHAM_LO!G2:G49,DL_CHAM_LO!C2:C49,2026,DL_CHAM_LO!D2:D49,A23) -> 29000000
A24: 3 | B24: =COUNTIFS(DL_CHAM_LO!C2:C49,2026,DL_CHAM_LO!D2:D49,A24) -> 14 | C24: =SUMIFS(DL_CHAM_LO!G2:G49,DL_CHAM_LO!C2:C49,2026,DL_CHAM_LO!D2:D49,A24) -> 7900000
A25: 4 | B25: =COUNTIFS(DL_CHAM_LO!C2:C49,2026,DL_CHAM_LO!D2:D49,A25) -> 7 | C25: =SUMIFS(DL_CHAM_LO!G2:G49,DL_CHAM_LO!C2:C49,2026,DL_CHAM_LO!D2:D49,A25) -> 9800000
A26: 5 | B26: =COUNTIFS(DL_CHAM_LO!C2:C49,2026,DL_CHAM_LO!D2:D49,A26) -> 6 | C26: =SUMIFS(DL_CHAM_LO!G2:G49,DL_CHAM_LO!C2:C49,2026,DL_CHAM_LO!D2:D49,A26) -> 9900000
A27: 6 | B27: =COUNTIFS(DL_CHAM_LO!C2:C49,2026,DL_CHAM_LO!D2:D49,A27) -> 6 | C27: =SUMIFS(DL_CHAM_LO!G2:G49,DL_CHAM_LO!C2:C49,2026,DL_CHAM_LO!D2:D49,A27) -> 6000000
A28: 7 | B28: =COUNTIFS(DL_CHAM_LO!C2:C49,2026,DL_CHAM_LO!D2:D49,A28) -> 6 | C28: =SUMIFS(DL_CHAM_LO!G2:G49,DL_CHAM_LO!C2:C49,2026,DL_CHAM_LO!D2:D49,A28) -> 3900000
A29: 8 | B29: =COUNTIFS(DL_CHAM_LO!C2:C49,2026,DL_CHAM_LO!D2:D49,A29) -> 0 | C29: =SUMIFS(DL_CHAM_LO!G2:G49,DL_CHAM_LO!C2:C49,2026,DL_CHAM_LO!D2:D49,A29) -> 0
A30: 9 | B30: =COUNTIFS(DL_CHAM_LO!C2:C49,2026,DL_CHAM_LO!D2:D49,A30) -> 0 | C30: =SUMIFS(DL_CHAM_LO!G2:G49,DL_CHAM_LO!C2:C49,2026,DL_CHAM_LO!D2:D49,A30) -> 0
A31: 10 | B31: =COUNTIFS(DL_CHAM_LO!C2:C49,2026,DL_CHAM_LO!D2:D49,A31) -> 0 | C31: =SUMIFS(DL_CHAM_LO!G2:G49,DL_CHAM_LO!C2:C49,2026,DL_CHAM_LO!D2:D49,A31) -> 0
A32: 11 | B32: =COUNTIFS(DL_CHAM_LO!C2:C49,2026,DL_CHAM_LO!D2:D49,A32) -> 0 | C32: =SUMIFS(DL_CHAM_LO!G2:G49,DL_CHAM_LO!C2:C49,2026,DL_CHAM_LO!D2:D49,A32) -> 0
A33: 12 | B33: =COUNTIFS(DL_CHAM_LO!C2:C49,2026,DL_CHAM_LO!D2:D49,A33) -> 0 | C33: =SUMIFS(DL_CHAM_LO!G2:G49,DL_CHAM_LO!C2:C49,2026,DL_CHAM_LO!D2:D49,A33) -> 0

Sheet AI_TRO_LY
A1: TRỢ LÝ – BỘ CÂU LỆNH HỖ TRỢ CÔNG TÁC CHĂM LO ĐOÀN VIÊN
A4: Chức năng | B4: Dữ liệu đầu vào tối thiểu | C4: Câu lệnh mẫu sử dụng với AI | D4: Kết quả cần kiểm tra
A5: Phân loại vụ việc | B5: Nội dung sự việc; quan hệ; hoàn cảnh | C5: Bạn là trợ lý công đoàn. Hãy phân loại trường hợp sau vào một trong các nhóm: Ốm đau, Hiếu, Hỷ/Sinh con, Tai nạn-rủi ro, Sinh nhật, Nghỉ việc hoặc Khác. Nêu lý do phân loại và hồ sơ cần bổ sung. Dữ liệu: [DÁN NỘI DUNG]. | D5: Đúng nhóm; không suy diễn thông tin cá nhân
A6: Kiểm tra hồ sơ | B6: Loại chăm lo; danh sách giấy tờ đã có | C6: Căn cứ danh mục hồ sơ nội bộ được cung cấp, hãy lập bảng gồm: hồ sơ đã có, hồ sơ còn thiếu, người chịu trách nhiệm bổ sung và hạn hoàn thành. Không tự đặt ra quy định mới. Dữ liệu: [DÁN NỘI DUNG]. | D6: Đối chiếu lại Quy chế Công đoàn
A7: Soạn giấy đề nghị | B7: Thông tin vụ việc; mức đề nghị; nguồn chi | C7: Hãy soạn Giấy đề nghị chi thăm hỏi đoàn viên theo văn phong hành chính, ngắn gọn, đủ căn cứ nội bộ, nêu rõ đối tượng, lý do, mức đề nghị và trách nhiệm hoàn thiện chứng từ. Dữ liệu: [DÁN NỘI DUNG]. | D7: Tên, số tiền, thời gian, người ký
A8: Soạn quyết định | B8: Danh sách đối tượng; loại hỗ trợ; số tiền | C8: Hãy soạn Quyết định chi hỗ trợ/thăm hỏi đoàn viên gồm căn cứ, điều khoản phê duyệt, danh sách kèm theo, nguồn chi và trách nhiệm thi hành. Dữ liệu: [DÁN NỘI DUNG]. | D8: Thẩm quyền và số tiền
A9: Lập báo cáo tháng | B9: Số lượt; số tiền; nhóm; địa bàn; tồn đọng | C9: Hãy viết báo cáo công tác chăm lo đoàn viên tháng [THÁNG] gồm kết quả thực hiện, cơ cấu đối tượng, kinh phí, trường hợp nổi bật, hồ sơ tồn đọng, khó khăn và nhiệm vụ tháng sau. Không nêu dữ liệu nhạy cảm không cần thiết. | D9: Số liệu phải khớp Dashboard
A10: Phân tích xu hướng | B10: Bảng dữ liệu đã ẩn thông tin định danh | C10: Hãy phân tích xu hướng chăm lo đoàn viên theo tháng, loại hỗ trợ và địa bàn; chỉ ra nhóm tăng bất thường, nguy cơ bỏ sót và đề xuất ưu tiên. Không đưa ra kết luận y tế hoặc đánh giá cá nhân. | D10: Ẩn danh trước khi gửi AI
A12: LƯU Ý: AI chỉ hỗ trợ phân loại, tổng hợp và soạn thảo. Ban Chấp hành Công đoàn phải kiểm tra lại nội dung, thẩm quyền, mức chi và hồ sơ trước khi phê duyệt. Không nhập dữ liệu cá nhân nhạy cảm lên nền tảng AI công cộng.
